<?xml version="1.0"?>
<robot name="simple_humanoid">
  <!-- Base link -->
  <link name="base_link">
    <inertial>
      <mass value="5.0"/>
      <origin xyz="0 0 0"/>
      <inertia ixx="0.1" ixy="0" ixz="0" iyy="0.1" iyz="0" izz="0.1"/>
    </inertial>
    <visual>
      <origin xyz="0 0 0"/>
      <geometry>
        <box size="0.3 0.3 0.3"/>
      </geometry>
    </visual>
    <collision>
      <origin xyz="0 0 0"/>
      <geometry>
        <box size="0.3 0.3 0.3"/>
      </geometry>
    </collision>
  </link>

  <!-- Left leg -->
  <link name="left_leg">
    <inertial>
      <mass value="2.0"/>
      <origin xyz="0 0 -0.5"/>
      <inertia ixx="0.05" ixy="0" ixz="0" iyy="0.05" iyz="0" izz="0.01"/>
    </inertial>
    <visual>
      <origin xyz="0 0 -0.5"/>
      <geometry>
        <cylinder length="1.0" radius="0.05"/>
      </geometry>
    </visual>
    <collision>
      <origin xyz="0 0 -0.5"/>
      <geometry>
        <cylinder length="1.0" radius="0.05"/>
      </geometry>
    </collision>
  </link>

  <!-- Right leg -->
  <link name="right_leg">
    <inertial>
      <mass value="2.0"/>
      <origin xyz="0 0 -0.5"/>
      <inertia ixx="0.05" ixy="0" ixz="0" iyy="0.05" iyz="0" izz="0.01"/>
    </inertial>
    <visual>
      <origin xyz="0 0 -0.5"/>
      <geometry>
        <cylinder length="1.0" radius="0.05"/>
      </geometry>
    </visual>
    <collision>
      <origin xyz="0 0 -0.5"/>
      <geometry>
        <cylinder length="1.0" radius="0.05"/>
      </geometry>
    </collision>
  </link>

  <!-- Left hip joint -->
  <joint name="left_hip_joint" type="revolute">
    <parent link="base_link"/>
    <child link="left_leg"/>
    <origin xyz="0.1 0 0"/>
    <axis xyz="0 0 1"/>
    <limit lower="-1.57" upper="1.57" effort="100" velocity="2"/>
    <dynamics damping="0.1" friction="0.01"/>
  </joint>

  <!-- Right hip joint -->
  <joint name="right_hip_joint" type="revolute">
    <parent link="base_link"/>
    <child link="right_leg"/>
    <origin xyz="-0.1 0 0"/>
    <axis xyz="0 0 1"/>
    <limit lower="-1.57" upper="1.57" effort="100" velocity="2"/>
    <dynamics damping="0.1" friction="0.01"/>
  </joint>
</robot>
